[2022-07-09 13:45:20,757] {taskinstance.py:1159} INFO - Dependencies all met for <TaskInstance: mysql_demo.CreateTable scheduled__2022-07-08T00:00:00+00:00 [queued]>
[2022-07-09 13:45:20,776] {taskinstance.py:1159} INFO - Dependencies all met for <TaskInstance: mysql_demo.CreateTable scheduled__2022-07-08T00:00:00+00:00 [queued]>
[2022-07-09 13:45:20,777] {taskinstance.py:1356} INFO - 
--------------------------------------------------------------------------------
[2022-07-09 13:45:20,778] {taskinstance.py:1357} INFO - Starting attempt 1 of 1
[2022-07-09 13:45:20,778] {taskinstance.py:1358} INFO - 
--------------------------------------------------------------------------------
[2022-07-09 13:45:20,800] {taskinstance.py:1377} INFO - Executing <Task(MySqlOperator): CreateTable> on 2022-07-08 00:00:00+00:00
[2022-07-09 13:45:20,807] {standard_task_runner.py:52} INFO - Started process 3469 to run task
[2022-07-09 13:45:20,817] {standard_task_runner.py:79} INFO - Running: ['***', 'tasks', 'run', 'mysql_demo', 'CreateTable', 'scheduled__2022-07-08T00:00:00+00:00', '--job-id', '29', '--raw', '--subdir', 'DAGS_FOLDER/mysql_demo.py', '--cfg-path', '/tmp/tmpue3fb0kd', '--error-file', '/tmp/tmpaunwcgi7']
[2022-07-09 13:45:20,818] {standard_task_runner.py:80} INFO - Job 29: Subtask CreateTable
[2022-07-09 13:45:20,894] {task_command.py:369} INFO - Running <TaskInstance: mysql_demo.CreateTable scheduled__2022-07-08T00:00:00+00:00 [running]> on host 3e3038753a11
[2022-07-09 13:45:21,008] {taskinstance.py:1571} INFO - Exporting the following env vars:
AIRFLOW_CTX_DAG_OWNER=***
AIRFLOW_CTX_DAG_ID=mysql_demo
AIRFLOW_CTX_TASK_ID=CreateTable
AIRFLOW_CTX_EXECUTION_DATE=2022-07-08T00:00:00+00:00
AIRFLOW_CTX_TRY_NUMBER=1
AIRFLOW_CTX_DAG_RUN_ID=scheduled__2022-07-08T00:00:00+00:00
[2022-07-09 13:45:21,014] {mysql.py:82} INFO - Executing:  CREATE TABLE ***_db.employee(empid int, empname VARCHAR(25), salary int); 
[2022-07-09 13:45:21,032] {base.py:68} INFO - Using connection ID 'mysql_conn' for task execution.
[2022-07-09 13:45:21,062] {taskinstance.py:1889} ERROR - Task failed with exception
Traceback (most recent call last):
  File "/home/airflow/.local/lib/python3.7/site-packages/airflow/providers/mysql/operators/mysql.py", line 84, in execute
    hook.run(self.sql, autocommit=self.autocommit, parameters=self.parameters)
  File "/home/airflow/.local/lib/python3.7/site-packages/airflow/hooks/dbapi.py", line 181, in run
    with closing(self.get_conn()) as conn:
  File "/home/airflow/.local/lib/python3.7/site-packages/airflow/providers/mysql/hooks/mysql.py", line 166, in get_conn
    return MySQLdb.connect(**conn_config)
  File "/home/airflow/.local/lib/python3.7/site-packages/MySQLdb/__init__.py", line 123, in Connect
    return Connection(*args, **kwargs)
  File "/home/airflow/.local/lib/python3.7/site-packages/MySQLdb/connections.py", line 185, in __init__
    super().__init__(*args, **kwargs2)
MySQLdb._exceptions.OperationalError: (2002, "Can't connect to local MySQL server through socket '/var/run/mysqld/mysqld.sock' (2)")
[2022-07-09 13:45:21,084] {taskinstance.py:1400} INFO - Marking task as FAILED. dag_id=mysql_demo, task_id=CreateTable, execution_date=20220708T000000, start_date=20220709T134520, end_date=20220709T134521
[2022-07-09 13:45:21,128] {standard_task_runner.py:97} ERROR - Failed to execute job 29 for task CreateTable ((2002, "Can't connect to local MySQL server through socket '/var/run/mysqld/mysqld.sock' (2)"); 3469)
[2022-07-09 13:45:21,150] {local_task_job.py:156} INFO - Task exited with return code 1
[2022-07-09 13:45:21,213] {local_task_job.py:273} INFO - 0 downstream tasks scheduled from follow-on schedule check
