[2022-07-07 02:28:17,680] {taskinstance.py:1159} INFO - Dependencies all met for <TaskInstance: client_processing_db.create_product scheduled__2022-07-06T00:00:00+00:00 [queued]>
[2022-07-07 02:28:17,694] {taskinstance.py:1159} INFO - Dependencies all met for <TaskInstance: client_processing_db.create_product scheduled__2022-07-06T00:00:00+00:00 [queued]>
[2022-07-07 02:28:17,695] {taskinstance.py:1356} INFO - 
--------------------------------------------------------------------------------
[2022-07-07 02:28:17,696] {taskinstance.py:1357} INFO - Starting attempt 1 of 1
[2022-07-07 02:28:17,697] {taskinstance.py:1358} INFO - 
--------------------------------------------------------------------------------
[2022-07-07 02:28:17,718] {taskinstance.py:1377} INFO - Executing <Task(MySqlOperator): create_product> on 2022-07-06 00:00:00+00:00
[2022-07-07 02:28:17,725] {standard_task_runner.py:52} INFO - Started process 2424 to run task
[2022-07-07 02:28:17,730] {standard_task_runner.py:79} INFO - Running: ['***', 'tasks', 'run', 'client_processing_db', 'create_product', 'scheduled__2022-07-06T00:00:00+00:00', '--job-id', '17', '--raw', '--subdir', 'DAGS_FOLDER/client_processing_db.py', '--cfg-path', '/tmp/tmphl2m3322', '--error-file', '/tmp/tmpk5r2wu10']
[2022-07-07 02:28:17,731] {standard_task_runner.py:80} INFO - Job 17: Subtask create_product
[2022-07-07 02:28:17,819] {task_command.py:369} INFO - Running <TaskInstance: client_processing_db.create_product scheduled__2022-07-06T00:00:00+00:00 [running]> on host 3e3038753a11
[2022-07-07 02:28:17,952] {taskinstance.py:1571} INFO - Exporting the following env vars:
AIRFLOW_CTX_DAG_OWNER=***
AIRFLOW_CTX_DAG_ID=client_processing_db
AIRFLOW_CTX_TASK_ID=create_product
AIRFLOW_CTX_EXECUTION_DATE=2022-07-06T00:00:00+00:00
AIRFLOW_CTX_TRY_NUMBER=1
AIRFLOW_CTX_DAG_RUN_ID=scheduled__2022-07-06T00:00:00+00:00
[2022-07-07 02:28:17,956] {mysql.py:82} INFO - Executing: 
            CREATE TABLE IF NOT EXISTS product (
                users_id INT NOT NULL PRIMARY KEY AUTO_INCREMENT,
                firstname TEXT NOT NULL,
                lastname TEXT NOT NULL,
                country TEXT NOT NULL,
                username TEXT NOT NULL UNIQUE,
                password TEXT NOT NULL,
                email TEXT NOT NULL UNIQUE
            );
        
[2022-07-07 02:28:17,986] {base.py:68} INFO - Using connection ID 'postgres' for task execution.
[2022-07-07 02:29:18,111] {taskinstance.py:1889} ERROR - Task failed with exception
Traceback (most recent call last):
  File "/home/airflow/.local/lib/python3.7/site-packages/airflow/providers/mysql/operators/mysql.py", line 84, in execute
    hook.run(self.sql, autocommit=self.autocommit, parameters=self.parameters)
  File "/home/airflow/.local/lib/python3.7/site-packages/airflow/hooks/dbapi.py", line 181, in run
    with closing(self.get_conn()) as conn:
  File "/home/airflow/.local/lib/python3.7/site-packages/airflow/providers/mysql/hooks/mysql.py", line 166, in get_conn
    return MySQLdb.connect(**conn_config)
  File "/home/airflow/.local/lib/python3.7/site-packages/MySQLdb/__init__.py", line 123, in Connect
    return Connection(*args, **kwargs)
  File "/home/airflow/.local/lib/python3.7/site-packages/MySQLdb/connections.py", line 185, in __init__
    super().__init__(*args, **kwargs2)
MySQLdb._exceptions.OperationalError: (2013, "Lost connection to MySQL server at 'reading initial communication packet', system error: 0")
[2022-07-07 02:29:18,135] {taskinstance.py:1400} INFO - Marking task as FAILED. dag_id=client_processing_db, task_id=create_product, execution_date=20220706T000000, start_date=20220707T022817, end_date=20220707T022918
[2022-07-07 02:29:18,176] {standard_task_runner.py:97} ERROR - Failed to execute job 17 for task create_product ((2013, "Lost connection to MySQL server at 'reading initial communication packet', system error: 0"); 2424)
[2022-07-07 02:29:18,226] {local_task_job.py:156} INFO - Task exited with return code 1
[2022-07-07 02:29:18,326] {local_task_job.py:273} INFO - 0 downstream tasks scheduled from follow-on schedule check
[2022-07-07 02:29:18,375] {dagrun.py:547} ERROR - Marking run <DagRun client_processing_db @ 2022-07-06 00:00:00+00:00: scheduled__2022-07-06T00:00:00+00:00, externally triggered: False> failed
[2022-07-07 02:29:18,377] {dagrun.py:622} INFO - DagRun Finished: dag_id=client_processing_db, execution_date=2022-07-06 00:00:00+00:00, run_id=scheduled__2022-07-06T00:00:00+00:00, run_start_date=2022-07-07 02:28:16.829350+00:00, run_end_date=2022-07-07 02:29:18.376905+00:00, run_duration=61.547555, state=failed, external_trigger=False, run_type=scheduled, data_interval_start=2022-07-06 00:00:00+00:00, data_interval_end=2022-07-07 00:00:00+00:00, dag_hash=5bc200cc260b7c7d9a6c5addae13a231
