[2022-07-09 15:14:03,034] {taskinstance.py:1159} INFO - Dependencies all met for <TaskInstance: mysql_demo.CreateTable manual__2022-07-09T15:14:00.912656+00:00 [queued]>
[2022-07-09 15:14:03,064] {taskinstance.py:1159} INFO - Dependencies all met for <TaskInstance: mysql_demo.CreateTable manual__2022-07-09T15:14:00.912656+00:00 [queued]>
[2022-07-09 15:14:03,066] {taskinstance.py:1356} INFO - 
--------------------------------------------------------------------------------
[2022-07-09 15:14:03,067] {taskinstance.py:1357} INFO - Starting attempt 1 of 1
[2022-07-09 15:14:03,068] {taskinstance.py:1358} INFO - 
--------------------------------------------------------------------------------
[2022-07-09 15:14:03,108] {taskinstance.py:1377} INFO - Executing <Task(MySqlOperator): CreateTable> on 2022-07-09 15:14:00.912656+00:00
[2022-07-09 15:14:03,115] {standard_task_runner.py:52} INFO - Started process 7799 to run task
[2022-07-09 15:14:03,130] {standard_task_runner.py:79} INFO - Running: ['***', 'tasks', 'run', 'mysql_demo', 'CreateTable', 'manual__2022-07-09T15:14:00.912656+00:00', '--job-id', '30', '--raw', '--subdir', 'DAGS_FOLDER/mysql_demo.py', '--cfg-path', '/tmp/tmpam8priym', '--error-file', '/tmp/tmpo6y071qe']
[2022-07-09 15:14:03,132] {standard_task_runner.py:80} INFO - Job 30: Subtask CreateTable
[2022-07-09 15:14:03,293] {task_command.py:369} INFO - Running <TaskInstance: mysql_demo.CreateTable manual__2022-07-09T15:14:00.912656+00:00 [running]> on host 3e3038753a11
[2022-07-09 15:14:03,640] {taskinstance.py:1571} INFO - Exporting the following env vars:
AIRFLOW_CTX_DAG_OWNER=***
AIRFLOW_CTX_DAG_ID=mysql_demo
AIRFLOW_CTX_TASK_ID=CreateTable
AIRFLOW_CTX_EXECUTION_DATE=2022-07-09T15:14:00.912656+00:00
AIRFLOW_CTX_TRY_NUMBER=1
AIRFLOW_CTX_DAG_RUN_ID=manual__2022-07-09T15:14:00.912656+00:00
[2022-07-09 15:14:03,653] {mysql.py:82} INFO - Executing:  CREATE TABLE ***_db.employee(empid int, empname VARCHAR(25), salary int); 
[2022-07-09 15:14:03,722] {base.py:68} INFO - Using connection ID 'mysql_conn' for task execution.
[2022-07-09 15:14:03,792] {taskinstance.py:1889} ERROR - Task failed with exception
Traceback (most recent call last):
  File "/home/airflow/.local/lib/python3.7/site-packages/airflow/providers/mysql/operators/mysql.py", line 84, in execute
    hook.run(self.sql, autocommit=self.autocommit, parameters=self.parameters)
  File "/home/airflow/.local/lib/python3.7/site-packages/airflow/hooks/dbapi.py", line 181, in run
    with closing(self.get_conn()) as conn:
  File "/home/airflow/.local/lib/python3.7/site-packages/airflow/providers/mysql/hooks/mysql.py", line 166, in get_conn
    return MySQLdb.connect(**conn_config)
  File "/home/airflow/.local/lib/python3.7/site-packages/MySQLdb/__init__.py", line 123, in Connect
    return Connection(*args, **kwargs)
  File "/home/airflow/.local/lib/python3.7/site-packages/MySQLdb/connections.py", line 185, in __init__
    super().__init__(*args, **kwargs2)
MySQLdb._exceptions.OperationalError: (2003, "Can't connect to MySQL server on '127.0.0.1:3306' (111)")
[2022-07-09 15:14:03,833] {taskinstance.py:1400} INFO - Marking task as FAILED. dag_id=mysql_demo, task_id=CreateTable, execution_date=20220709T151400, start_date=20220709T151403, end_date=20220709T151403
[2022-07-09 15:14:03,878] {standard_task_runner.py:97} ERROR - Failed to execute job 30 for task CreateTable ((2003, "Can't connect to MySQL server on '127.0.0.1:3306' (111)"); 7799)
[2022-07-09 15:14:03,907] {local_task_job.py:156} INFO - Task exited with return code 1
[2022-07-09 15:14:04,042] {local_task_job.py:273} INFO - 0 downstream tasks scheduled from follow-on schedule check
