[2022-07-08 02:36:34,978] {taskinstance.py:1159} INFO - Dependencies all met for <TaskInstance: client_processing_db.create_attendance scheduled__2022-07-07T00:00:00+00:00 [queued]>
[2022-07-08 02:36:35,008] {taskinstance.py:1159} INFO - Dependencies all met for <TaskInstance: client_processing_db.create_attendance scheduled__2022-07-07T00:00:00+00:00 [queued]>
[2022-07-08 02:36:35,010] {taskinstance.py:1356} INFO - 
--------------------------------------------------------------------------------
[2022-07-08 02:36:35,011] {taskinstance.py:1357} INFO - Starting attempt 1 of 1
[2022-07-08 02:36:35,012] {taskinstance.py:1358} INFO - 
--------------------------------------------------------------------------------
[2022-07-08 02:36:35,046] {taskinstance.py:1377} INFO - Executing <Task(MySqlOperator): create_attendance> on 2022-07-07 00:00:00+00:00
[2022-07-08 02:36:35,058] {standard_task_runner.py:52} INFO - Started process 11460 to run task
[2022-07-08 02:36:35,065] {standard_task_runner.py:79} INFO - Running: ['***', 'tasks', 'run', 'client_processing_db', 'create_attendance', 'scheduled__2022-07-07T00:00:00+00:00', '--job-id', '25', '--raw', '--subdir', 'DAGS_FOLDER/client_processing_db.py', '--cfg-path', '/tmp/tmpnxlhbncb', '--error-file', '/tmp/tmp6mbb4zhs']
[2022-07-08 02:36:35,076] {standard_task_runner.py:80} INFO - Job 25: Subtask create_attendance
[2022-07-08 02:36:35,544] {task_command.py:369} INFO - Running <TaskInstance: client_processing_db.create_attendance scheduled__2022-07-07T00:00:00+00:00 [running]> on host 3e3038753a11
[2022-07-08 02:36:35,908] {taskinstance.py:1571} INFO - Exporting the following env vars:
AIRFLOW_CTX_DAG_OWNER=***
AIRFLOW_CTX_DAG_ID=client_processing_db
AIRFLOW_CTX_TASK_ID=create_attendance
AIRFLOW_CTX_EXECUTION_DATE=2022-07-07T00:00:00+00:00
AIRFLOW_CTX_TRY_NUMBER=1
AIRFLOW_CTX_DAG_RUN_ID=scheduled__2022-07-07T00:00:00+00:00
[2022-07-08 02:36:35,910] {mysql.py:82} INFO - Executing: 
            CREATE TABLE IF NOT EXISTS staff (
                users_id INT NOT NULL PRIMARY KEY AUTO_INCREMENT,
                firstname TEXT NOT NULL,
                lastname TEXT NOT NULL,
                country TEXT NOT NULL,
                username TEXT NOT NULL UNIQUE,
                password TEXT NOT NULL,
                email TEXT NOT NULL UNIQUE
            );
        
[2022-07-08 02:36:35,938] {base.py:68} INFO - Using connection ID 'postgres' for task execution.
[2022-07-08 02:37:35,972] {taskinstance.py:1889} ERROR - Task failed with exception
Traceback (most recent call last):
  File "/home/airflow/.local/lib/python3.7/site-packages/airflow/providers/mysql/operators/mysql.py", line 84, in execute
    hook.run(self.sql, autocommit=self.autocommit, parameters=self.parameters)
  File "/home/airflow/.local/lib/python3.7/site-packages/airflow/hooks/dbapi.py", line 181, in run
    with closing(self.get_conn()) as conn:
  File "/home/airflow/.local/lib/python3.7/site-packages/airflow/providers/mysql/hooks/mysql.py", line 166, in get_conn
    return MySQLdb.connect(**conn_config)
  File "/home/airflow/.local/lib/python3.7/site-packages/MySQLdb/__init__.py", line 123, in Connect
    return Connection(*args, **kwargs)
  File "/home/airflow/.local/lib/python3.7/site-packages/MySQLdb/connections.py", line 185, in __init__
    super().__init__(*args, **kwargs2)
MySQLdb._exceptions.OperationalError: (2013, "Lost connection to MySQL server at 'reading initial communication packet', system error: 0")
[2022-07-08 02:37:36,004] {taskinstance.py:1400} INFO - Marking task as FAILED. dag_id=client_processing_db, task_id=create_attendance, execution_date=20220707T000000, start_date=20220708T023634, end_date=20220708T023736
[2022-07-08 02:37:36,023] {standard_task_runner.py:97} ERROR - Failed to execute job 25 for task create_attendance ((2013, "Lost connection to MySQL server at 'reading initial communication packet', system error: 0"); 11460)
[2022-07-08 02:37:36,061] {local_task_job.py:156} INFO - Task exited with return code 1
[2022-07-08 02:37:36,103] {local_task_job.py:273} INFO - 0 downstream tasks scheduled from follow-on schedule check
[2022-07-08 02:37:36,131] {dagrun.py:547} ERROR - Marking run <DagRun client_processing_db @ 2022-07-07 00:00:00+00:00: scheduled__2022-07-07T00:00:00+00:00, externally triggered: False> failed
[2022-07-08 02:37:36,132] {dagrun.py:622} INFO - DagRun Finished: dag_id=client_processing_db, execution_date=2022-07-07 00:00:00+00:00, run_id=scheduled__2022-07-07T00:00:00+00:00, run_start_date=2022-07-08 02:36:32.956559+00:00, run_end_date=2022-07-08 02:37:36.132561+00:00, run_duration=63.176002, state=failed, external_trigger=False, run_type=scheduled, data_interval_start=2022-07-07 00:00:00+00:00, data_interval_end=2022-07-08 00:00:00+00:00, dag_hash=5bc200cc260b7c7d9a6c5addae13a231
